2025-03-19 02:42:57,055 - asyncio - ERROR - Future exception was never retrieved
future: <Future finished exception=AttributeError("'ModificarTurno' object has no attribute 'tecnico_dropdown'")>
Traceback (most recent call last):
  File "C:\Users\BashDeep\AppData\Local\Programs\Python\Python313\Lib\concurrent\futures\thread.py", line 59, in run
    result = self.fn(*self.args, **self.kwargs)
  File "C:\Users\BashDeep\AppData\Local\Programs\Python\Python313\Lib\site-packages\flet\core\page.py", line 948, in wrapper
    handler(*args)
    ~~~~~~~^^^^^^^
  File "c:\Users\BashDeep\Documents\Apps\SoftwareProjects\CalendarManager\views\calendario_view.py", line 421, in <lambda>
    on_click=lambda e, t=turno: self.modificar_turno_handler(t)
                                ~~~~~~~~~~~~~~~~~~~~~~~~~~~~^^^
  File "c:\Users\BashDeep\Documents\Apps\SoftwareProjects\CalendarManager\views\calendario_view.py", line 449, in modificar_turno_handler
    if self.modificar_turno.editar_turno(turno):
       ~~~~~~~~~~~~~~~~~~~~~~~~~~~~~~~~~^^^^^^^
  File "c:\Users\BashDeep\Documents\Apps\SoftwareProjects\CalendarManager\views\modificar_turno.py", line 134, in editar_turno
    self.tecnico_dropdown
AttributeError: 'ModificarTurno' object has no attribute 'tecnico_dropdown'. Did you mean: 'tecnico_dropwdown'?
